<mujoco model="single_leg">
  <option gravity="0 0 -9.81"/>
  
  <worldbody>
    <geom type="plane" size="1 1 0.1" rgba="0.9 0.9 0.9 1"/>
    
    <body name="base_link" pos="0 0 1.0">
      <geom type="box" size="0.05 0.05 0.05" rgba="0.5 0.5 0.5 1"/>
      <body name="hip_aa_link" pos="0 0 -0.05">
        <joint name="hip_aa_joint" type="hinge" axis="1 0 0" range="-1.57 1.57" damping="1.0"/>
        <inertial pos="0 0 0" mass="0.5" diaginertia="0.005 0.005 0.005"/>
        <geom type="sphere" size="0.03" rgba="0 0.8 0 1"/>
        
        <body name="thigh_link" pos="0 0 -0.05">
          <joint name="hip_joint" type="hinge" axis="0 1 0" range="-1.57 1.57" damping="1.0"/>
          <inertial pos="0 0 -0.2" mass="1.0" diaginertia="0.01 0.01 0.01"/>
          <geom type="cylinder" size="0.02 0.2" pos="0 0 -0.2" rgba="0.8 0 0 1"/>
          
          <body name="calf_link" pos="0 0 -0.4">
            <joint name="knee_joint" type="hinge" axis="0 1 0" range="-1.57 1.57" damping="1.0"/>
            <inertial pos="0 0 -0.2" mass="1.0" diaginertia="0.01 0.01 0.01"/>
            <geom type="cylinder" size="0.02 0.2" pos="0 0 -0.2" rgba="0 0 0.8 1"/>
            
            <geom name="foot" type="sphere" size="0.02" pos="0 0 -0.4" rgba="1 1 0 1"/>
          </body>
        </body>
      </body>
    </body>
  </worldbody>
</mujoco>